# Werkzeug Routing Error Analysis: order_tracking Endpoint

## Error Description
```
werkzeug.routing.exceptions.BuildError: Could not build url for endpoint 'order_tracking'. Did you forget to specify values ['order_id']?
```

## Root Cause Analysis

The error occurs when Flask's `url_for()` function tries to build a URL for the `order_tracking` endpoint but cannot find a required parameter `order_id`. The route is defined as:

```python
@app.route('/order/<int:order_id>')
@login_required
def order_tracking(order_id):
```

This route requires an `order_id` parameter to build the URL, but somewhere in the code, there's a `url_for('order_tracking')` call that's missing this parameter.

## Investigation Results

After comprehensive code analysis, I found all instances of `url_for('order_tracking')` in the codebase:

### Routes.py (All instances correctly provide order_id):
- Line 420: `url_for('order_tracking', order_id=order.id)` - in `finalize_order` function
- Line 476: `url_for('order_tracking', order_id=order.id)` - in `update_order_status` function  
- Line 753: `url_for('order_tracking', order_id=order.id)` - in `rate_order` function
- Line 758: `url_for('order_tracking', order_id=order.id)` - in `rate_order` function
- Line 765: `url_for('order_tracking', order_id=order.id)` - in `rate_order` function

### Templates (All instances correctly provide order_id):
- `admin_orders.html` line 119: `url_for('order_tracking', order_id=order.id)`
- `customer_dashboard.html` line 27: `url_for('order_tracking', order_id=order.id)`
- `admin_dashboard.html` line 268: `url_for('order_tracking', order_id=order.id)`

## Potential Root Causes

Since all visible `url_for('order_tracking')` calls include the `order_id` parameter, the issue likely stems from:

### 1. **order.id is None**
The most probable cause is that in one of the contexts, the `order.id` value is `None` or undefined. This can happen if:
- The order object was created but not committed to the database
- A database transaction failed
- The order object is not properly initialized
- The order is queried but doesn't exist

### 2. **Database Transaction Issues**
In the `finalize_order` function (line 420), there's a database commit right before the redirect:
```python
db.session.commit()
return redirect(url_for('order_tracking', order_id=order.id))
```

If the commit fails silently or there's a rollback, `order.id` might be None.

### 3. **Template Context Issues**
In templates where `order.id` is used, if the `order` object is not properly passed to the template context or is None, this error would occur.

## Recommended Solutions

### Solution 1: Add Defensive Checks
Add validation before using `order.id` in `url_for` calls:

```python
# In routes.py, before redirect calls:
if not order or not order.id:
    flash('Order not found or invalid.', 'error')
    return redirect(url_for('customer_dashboard'))

return redirect(url_for('order_tracking', order_id=order.id))
```

### Solution 2: Add Database Commit Error Handling
Wrap database operations in try-catch blocks:

```python
try:
    db.session.commit()
    if order.id:
        return redirect(url_for('order_tracking', order_id=order.id))
    else:
        raise Exception("Order ID not generated")
except Exception as e:
    db.session.rollback()
    flash('An error occurred while processing your order.', 'error')
    return redirect(url_for('customer_dashboard'))
```

### Solution 3: Add Template Safety Checks
In templates, add checks before using `order.id`:

```html
{% if order and order.id %}
    <a href="{{ url_for('order_tracking', order_id=order.id) }}">{{ order.order_number }}</a>
{% else %}
    <span>Order information unavailable</span>
{% endif %}
```

### Solution 4: Add Global Error Handler
Add a global error handler for this specific error:

```python
@app.errorhandler(werkzeug.routing.exceptions.BuildError)
def handle_build_error(e):
    flash('URL generation error. Please try again.', 'error')
    return redirect(url_for('index'))
```

## Specific Fixes to Implement

### Fix 1: Update finalize_order function
```python
@app.route('/order/<int:order_id>/finalize', methods=['POST'])
@login_required
def finalize_order(order_id):
    order = Order.query.get_or_404(order_id)
    
    # ... existing code ...
    
    try:
        db.session.commit()
        # Verify order has an ID after commit
        if not order.id:
            raise ValueError("Order ID not generated after database commit")
        
        session.pop('current_order_id', None)
        flash('Order finalized successfully!', 'success')
        return redirect(url_for('order_tracking', order_id=order.id))
    except Exception as e:
        db.session.rollback()
        flash('An error occurred while finalizing your order. Please try again.', 'error')
        return redirect(url_for('customer_dashboard'))
```

### Fix 2: Update template safety
Add checks in templates that use `order.id`:

```html
<!-- In customer_dashboard.html -->
{% if order and order.id %}
    <td><a href="{{ url_for('order_tracking', order_id=order.id) }}">{{ order.order_number }}</a></td>
{% else %}
    <td>Order ID unavailable</td>
{% endif %}
```

### Fix 3: Add logging for debugging
Add logging to track when order.id might be None:

```python
import logging

# Before url_for calls:
if not order or not order.id:
    logging.error(f"Order or order.id is None in function {function_name}")
    # Handle the error appropriately
```

## Prevention Measures

1. **Always validate order objects** before using them in `url_for` calls
2. **Add proper error handling** around database operations
3. **Use database transactions** properly with rollback on errors
4. **Add logging** to track when orders might have None IDs
5. **Consider using UUIDs** instead of auto-incrementing IDs for more reliability

## Testing Strategy

1. Test order creation and finalization flow
2. Test with database connection issues
3. Test with invalid order IDs
4. Test template rendering with None orders
5. Add unit tests for edge cases

This comprehensive analysis should help identify and fix the root cause of the `werkzeug.routing.exceptions.BuildError` for the `order_tracking` endpoint.